Workbook

Sheet Hoja1
A1: REPORTE DE GASTOS DE VIAJE
A2: INSTITUCION | B2: INSTITUTO DOMINICANO DE LAS TELECOMUNICACIONES
A3: DEPARTAMENTO
A4: NOMBRE DEL VIAJERO | B4: Claudio Miguel Peguero Castillo
A5: CEDULA | B5: 001-123065-5
A6: DESTINO DEL VIAJE | B6: Viena, Austria | G6: FECHA DE SALIDA | H6: 46041 | I6: FECHA DE REGRESO | L6: 46053
A7: NOMBRE DEL EVENTO | B7: Sesión Comité Ad-Hoc Ciberdelitos ONU
A8: FECHA CONSUMO | B8: NUMERO DE FACTURA | C8: DESCRIPCION O NOMBRE COMERCIO | D8: MONTO
D9: HOTEL | E9: COMIDA | F9: TRANSPORTE | G9: COMUNICACIÓN | H9: VARIOS | I9: TIPO DE MONEDA | J9: SUB-TOTAL | K9: TASA DE CAMBIO | L9: TOTAL RD$
A10: 46042 | B10: MCK9KC4C-242 | C10: Traslado aeropuerto-hotel | H10: 60 | I10: EURO | J10: =SUM(D10:H10) -> 60 | K10: 78 | L10: =+J10*K10 -> 4680
A11: 46042 | B11: 72070214603500 | C11: Hotel Melia Viena | D11: 2002.33 | I11: USD | J11: =SUM(D11:H11) -> 2002.33 | K11: 63.75 | L11: =+J11*K11 -> 127648.54
A12: 46043 | B12: 3605 | C12: Paco Ribera | E12: 65.5 | I12: EURO | J12: =SUM(D12:H12) -> 65.5 | K12: 78 | L12: =+J12*K12 -> 5109
A13: 46043 | B13: 2065 | C13: Ginza | E13: 82.9 | I13: EURO | J13: =SUM(D13:H13) -> 82.9 | K13: 78 | L13: =+J13*K13 -> 6466.2
A14: 46043 | C14: Transporte | H14: 26.4 | I14: EURO | J14: =SUM(D14:H14) -> 26.4 | K14: 78 | L14: =+J14*K14 -> 2059.2
A15: 46044 | B15: 33247 | C15: Sha Guo | E15: 55.8 | I15: EURO | J15: =SUM(D15:H15) -> 55.8 | K15: 78 | L15: =+J15*K15 -> 4352.4
A16: 46044 | B16: 86402 | C16: Lugeck | E16: 75.68 | I16: EURO | J16: =SUM(D16:H16) -> 75.68 | K16: 78 | L16: =+J16*K16 -> 5903.04
A17: 46044 | C17: Transporte | H17: 37.37 | I17: EURO | J17: =SUM(D17:H17) -> 37.37 | K17: 78 | L17: =+J17*K17 -> 2914.86
A18: 46045 | B18: 132 | C18: El Gaucho | E18: 73.9 | I18: EURO | J18: =SUM(D18:H18) -> 73.9 | K18: 78 | L18: =+J18*K18 -> 5764.2
A19: 46045 | B19: 6472 | C19: Altia | E19: 106 | I19: EURO | J19: =SUM(D19:H19) -> 106 | K19: 78 | L19: =+J19*K19 -> 8268
A20: 46045 | C20: Transporte | H20: 105.72 | I20: EURO | J20: =SUM(D20:H20) -> 105.72 | K20: 78 | L20: =+J20*K20 -> 8246.16
A21: 46046 | B21: 3304 | C21: Sha Guo | E21: 49.7 | I21: EURO | J21: =SUM(D21:H21) -> 49.7 | K21: 78 | L21: =+J21*K21 -> 3876.6
A22: 46046 | B22: 64671 | C22: Beef & Glory | E22: 170.5 | I22: EURO | J22: =SUM(D22:H22) -> 170.5 | K22: 78 | L22: =+J22*K22 -> 13299
A23: 46046 | C23: Transporte | H23: 85.74 | I23: EURO | J23: =SUM(D23:H23) -> 85.74 | K23: 78 | L23: =+J23*K23 -> 6687.72
A24: 46047 | B24: 84183 | C24: Plachuttas | E24: 97.57 | I24: EURO | J24: =SUM(D24:H24) -> 97.57 | K24: 78 | L24: =+J24*K24 -> 7610.46
A25: 46047 | B25: 4319 | C25: Glasswing | E25: 257 | I25: EURO | J25: =SUM(D25:H25) -> 257 | K25: 78 | L25: =+J25*K25 -> 20046
A26: 46047 | C26: Transporte | H26: 28.42 | I26: EURO | J26: =SUM(D26:H26) -> 28.42 | K26: 78 | L26: =+J26*K26 -> 2216.76
A27: 46048 | B27: 3247 | C27: Strandcafe | E27: 77.3 | I27: EURO | J27: =SUM(D27:H27) -> 77.3 | K27: 78 | L27: =+J27*K27 -> 6029.4
A28: 46048 | B28: 87754 | C28: Lugeck | E28: 94.16 | I28: EURO | J28: =SUM(D28:H28) -> 94.16 | K28: 78 | L28: =+J28*K28 -> 7344.48
A29: 46048 | C29: Transporte | H29: 29.31 | I29: EURO | J29: =SUM(D29:H29) -> 29.31 | K29: 78 | L29: =+J29*K29 -> 2286.18
A30: 46049 | B30: 33407 | C30: Sha Guo | E30: 65.9 | I30: EURO | J30: =SUM(D30:H30) -> 65.9 | K30: 78 | L30: =+J30*K30 -> 5140.2
A31: 46049 | B31: 2631 | C31: Grune Bar | E31: 159.6 | I31: EURO | J31: =SUM(D31:H31) -> 159.6 | K31: 78 | L31: =+J31*K31 -> 12448.8
A32: 46049 | C32: Transporte | H32: 34.4 | I32: EURO | J32: =SUM(D32:H32) -> 34.4 | K32: 78 | L32: =+J32*K32 -> 2683.2
A33: 46050 | B33: 5274 | C33: Restaurant UNO | E33: 75.9 | I33: EURO | J33: =SUM(D33:H33) -> 75.9 | K33: 78 | L33: =+J33*K33 -> 5920.2
A34: 46050 | B34: 63478 | C34: Da Capo | E34: 74.6 | I34: EURO | J34: =SUM(D34:H34) -> 74.6 | K34: 78 | L34: =+J34*K34 -> 5818.8
A35: 46050 | C35: Transporte | H35: 22.29 | I35: EURO | J35: =SUM(D35:H35) -> 22.29 | K35: 78 | L35: =+J35*K35 -> 1738.62
A36: 46051 | B36: 3827 | C36: Paco Ribera | E36: 58 | I36: EURO | J36: =SUM(D36:H36) -> 58 | K36: 78 | L36: =+J36*K36 -> 4524
A37: 46051 | B37: 105 | C37: Onyx | E37: 328 | I37: EURO | J37: =SUM(D37:H37) -> 328 | K37: 78 | L37: =+J37*K37 -> 25584
A38: 46051 | C38: Transporte | H38: 32.38 | I38: EURO | J38: =SUM(D38:H38) -> 32.38 | K38: 78 | L38: =+J38*K38 -> 2525.64
A39: 46052 | B39: 33442 | C39: Restaurant UNO | E39: 71.5 | I39: EURO | J39: =SUM(D39:H39) -> 71.5 | K39: 78 | L39: =+J39*K39 -> 5577
A40: 46052 | C40: Daihachi Sushi | E40: 73.5 | I40: EURO | J40: =SUM(D40:H40) -> 73.5 | K40: 78 | L40: =+J40*K40 -> 5733
...

Sheet Hoja2
A1: REPORTE DE GASTOS DE VIAJE
A2: INSTITUCION | B2: INSTITUTO DOMINICANO DE LAS TELECOMUNICACIONES
A3: DEPARTAMENTO
A4: NOMBRE DEL VIAJERO | B4: =+Hoja1!B4 -> Claudio Miguel Peguero Castillo
A5: CEDULA | B5: =+Hoja1!B5 -> 001-123065-5
A6: DESTINO DEL VIAJE | B6: =+Hoja1!B6 -> Viena, Austria | G6: FECHA DE SALIDA | H6: =+Hoja1!H6 -> 46041 | I6: FECHA DE REGRESO | L6: =+Hoja1!L6 -> 46053
A7: NOMBRE DEL EVENTO | B7: =+Hoja1!B7 -> Sesión Comité Ad-Hoc Ciberdelitos ONU
D8: AVANCE A SERVIDOR EN CHEQUE / LB | G8: =+Hoja1!L47 -> 503449.2
D9: 20% GASTOS MENORES | G9: =+G8*20% -> 100689.84
D10: TOTAL VIATICOS | G10: =+G11+G9 -> 436076.56
D11: GASTOS REALIZADOS | G11: =+Hoja1!L46 -> 335386.72
D12: RESTANTE A DEVOLVER | G12: =+Hoja1!L48 -> 67372.642
